[2020-09-18 12:45:29 +0000] [1] [INFO] Starting gunicorn 20.0.4
[2020-09-18 12:45:29 +0000] [1] [INFO] Listening at: http://0.0.0.0:5000 (1)
[2020-09-18 12:45:29 +0000] [1] [INFO] Using worker: sync
[2020-09-18 12:45:29 +0000] [7] [INFO] Booting worker with pid: 7
[2020-09-18 12:45:29 +0000] [8] [INFO] Booting worker with pid: 8
[2020-09-18 12:45:29 +0000] [9] [INFO] Booting worker with pid: 9
[2020-09-18 20:59:49 +0000] [1] [CRITICAL] WORKER TIMEOUT (pid:7)
[2020-09-18 20:59:49 +0000] [1] [CRITICAL] WORKER TIMEOUT (pid:8)
[2020-09-18 20:59:49 +0000] [1] [CRITICAL] WORKER TIMEOUT (pid:9)
[2020-09-18 20:59:49 +0000] [10] [INFO] Booting worker with pid: 10
[2020-09-18 20:59:49 +0000] [11] [INFO] Booting worker with pid: 11
[2020-09-18 20:59:49 +0000] [12] [INFO] Booting worker with pid: 12
[2020-09-20 09:12:01 +0000] [1] [INFO] Starting gunicorn 20.0.4
[2020-09-20 09:12:01 +0000] [1] [INFO] Listening at: http://0.0.0.0:5000 (1)
[2020-09-20 09:12:01 +0000] [1] [INFO] Using worker: sync
[2020-09-20 09:12:01 +0000] [7] [INFO] Booting worker with pid: 7
[2020-09-20 09:12:01 +0000] [8] [INFO] Booting worker with pid: 8
[2020-09-20 09:12:01 +0000] [9] [INFO] Booting worker with pid: 9
[2020-09-20 14:26:30 +0000] [1] [INFO] Handling signal: term
[2020-09-20 14:26:30 +0000] [1] [INFO] Shutting down: Master
[2020-09-20 14:26:32 +0000] [1] [INFO] Starting gunicorn 20.0.4
[2020-09-20 14:26:32 +0000] [1] [INFO] Listening at: http://0.0.0.0:5000 (1)
[2020-09-20 14:26:32 +0000] [1] [INFO] Using worker: sync
[2020-09-20 14:26:32 +0000] [7] [INFO] Booting worker with pid: 7
[2020-09-20 14:26:32 +0000] [8] [INFO] Booting worker with pid: 8
[2020-09-20 14:26:32 +0000] [9] [INFO] Booting worker with pid: 9
Traceback (most recent call last):
  File "/usr/local/lib/python3.8/dist-packages/gunicorn/arbiter.py", line 209, in run
    self.sleep()
  File "/usr/local/lib/python3.8/dist-packages/gunicorn/arbiter.py", line 357, in sleep
    ready = select.select([self.PIPE[0]], [], [], 1.0)
  File "/usr/local/lib/python3.8/dist-packages/gunicorn/arbiter.py", line 242, in handle_chld
    self.reap_workers()
  File "/usr/local/lib/python3.8/dist-packages/gunicorn/arbiter.py", line 525, in reap_workers
    raise HaltServer(reason, self.WORKER_BOOT_ERROR)
gunicorn.errors.HaltServer: <HaltServer 'Worker failed to boot.' 3>

During handling of the above exception, another exception occurred:

Traceback (most recent call last):
  File "/usr/local/bin/gunicorn", line 8, in <module>
    sys.exit(run())
  File "/usr/local/lib/python3.8/dist-packages/gunicorn/app/wsgiapp.py", line 58, in run
    WSGIApplication("%(prog)s [OPTIONS] [APP_MODULE]").run()
  File "/usr/local/lib/python3.8/dist-packages/gunicorn/app/base.py", line 228, in run
    super().run()
  File "/usr/local/lib/python3.8/dist-packages/gunicorn/app/base.py", line 72, in run
    Arbiter(self).run()
  File "/usr/local/lib/python3.8/dist-packages/gunicorn/arbiter.py", line 229, in run
    self.halt(reason=inst.reason, exit_status=inst.exit_status)
  File "/usr/local/lib/python3.8/dist-packages/gunicorn/arbiter.py", line 342, in halt
    self.stop()
  File "/usr/local/lib/python3.8/dist-packages/gunicorn/arbiter.py", line 393, in stop
    time.sleep(0.1)
  File "/usr/local/lib/python3.8/dist-packages/gunicorn/arbiter.py", line 242, in handle_chld
    self.reap_workers()
  File "/usr/local/lib/python3.8/dist-packages/gunicorn/arbiter.py", line 525, in reap_workers
    raise HaltServer(reason, self.WORKER_BOOT_ERROR)
gunicorn.errors.HaltServer: <HaltServer 'Worker failed to boot.' 3>
[2020-09-20 14:27:26 +0000] [1] [INFO] Starting gunicorn 20.0.4
[2020-09-20 14:27:26 +0000] [1] [INFO] Listening at: http://0.0.0.0:5000 (1)
[2020-09-20 14:27:26 +0000] [1] [INFO] Using worker: sync
[2020-09-20 14:27:26 +0000] [7] [INFO] Booting worker with pid: 7
[2020-09-20 14:27:26 +0000] [8] [INFO] Booting worker with pid: 8
[2020-09-20 14:27:26 +0000] [9] [INFO] Booting worker with pid: 9
Traceback (most recent call last):
  File "/usr/local/lib/python3.8/dist-packages/gunicorn/arbiter.py", line 209, in run
    self.sleep()
  File "/usr/local/lib/python3.8/dist-packages/gunicorn/arbiter.py", line 357, in sleep
    ready = select.select([self.PIPE[0]], [], [], 1.0)
  File "/usr/local/lib/python3.8/dist-packages/gunicorn/arbiter.py", line 242, in handle_chld
    self.reap_workers()
  File "/usr/local/lib/python3.8/dist-packages/gunicorn/arbiter.py", line 525, in reap_workers
    raise HaltServer(reason, self.WORKER_BOOT_ERROR)
gunicorn.errors.HaltServer: <HaltServer 'Worker failed to boot.' 3>

During handling of the above exception, another exception occurred:

Traceback (most recent call last):
  File "/usr/local/bin/gunicorn", line 8, in <module>
    sys.exit(run())
  File "/usr/local/lib/python3.8/dist-packages/gunicorn/app/wsgiapp.py", line 58, in run
    WSGIApplication("%(prog)s [OPTIONS] [APP_MODULE]").run()
  File "/usr/local/lib/python3.8/dist-packages/gunicorn/app/base.py", line 228, in run
    super().run()
  File "/usr/local/lib/python3.8/dist-packages/gunicorn/app/base.py", line 72, in run
    Arbiter(self).run()
  File "/usr/local/lib/python3.8/dist-packages/gunicorn/arbiter.py", line 229, in run
    self.halt(reason=inst.reason, exit_status=inst.exit_status)
  File "/usr/local/lib/python3.8/dist-packages/gunicorn/arbiter.py", line 342, in halt
    self.stop()
  File "/usr/local/lib/python3.8/dist-packages/gunicorn/arbiter.py", line 393, in stop
    time.sleep(0.1)
  File "/usr/local/lib/python3.8/dist-packages/gunicorn/arbiter.py", line 242, in handle_chld
    self.reap_workers()
  File "/usr/local/lib/python3.8/dist-packages/gunicorn/arbiter.py", line 525, in reap_workers
    raise HaltServer(reason, self.WORKER_BOOT_ERROR)
gunicorn.errors.HaltServer: <HaltServer 'Worker failed to boot.' 3>
[2020-09-20 14:28:09 +0000] [1] [INFO] Starting gunicorn 20.0.4
[2020-09-20 14:28:09 +0000] [1] [INFO] Listening at: http://0.0.0.0:5000 (1)
[2020-09-20 14:28:09 +0000] [1] [INFO] Using worker: sync
[2020-09-20 14:28:09 +0000] [7] [INFO] Booting worker with pid: 7
[2020-09-20 14:28:10 +0000] [8] [INFO] Booting worker with pid: 8
[2020-09-20 14:28:10 +0000] [9] [INFO] Booting worker with pid: 9
Traceback (most recent call last):
  File "/usr/local/lib/python3.8/dist-packages/gunicorn/arbiter.py", line 209, in run
    self.sleep()
  File "/usr/local/lib/python3.8/dist-packages/gunicorn/arbiter.py", line 357, in sleep
    ready = select.select([self.PIPE[0]], [], [], 1.0)
  File "/usr/local/lib/python3.8/dist-packages/gunicorn/arbiter.py", line 242, in handle_chld
    self.reap_workers()
  File "/usr/local/lib/python3.8/dist-packages/gunicorn/arbiter.py", line 525, in reap_workers
    raise HaltServer(reason, self.WORKER_BOOT_ERROR)
gunicorn.errors.HaltServer: <HaltServer 'Worker failed to boot.' 3>

During handling of the above exception, another exception occurred:

Traceback (most recent call last):
  File "/usr/local/bin/gunicorn", line 8, in <module>
    sys.exit(run())
  File "/usr/local/lib/python3.8/dist-packages/gunicorn/app/wsgiapp.py", line 58, in run
    WSGIApplication("%(prog)s [OPTIONS] [APP_MODULE]").run()
  File "/usr/local/lib/python3.8/dist-packages/gunicorn/app/base.py", line 228, in run
    super().run()
  File "/usr/local/lib/python3.8/dist-packages/gunicorn/app/base.py", line 72, in run
    Arbiter(self).run()
  File "/usr/local/lib/python3.8/dist-packages/gunicorn/arbiter.py", line 229, in run
    self.halt(reason=inst.reason, exit_status=inst.exit_status)
  File "/usr/local/lib/python3.8/dist-packages/gunicorn/arbiter.py", line 342, in halt
    self.stop()
  File "/usr/local/lib/python3.8/dist-packages/gunicorn/arbiter.py", line 393, in stop
    time.sleep(0.1)
  File "/usr/local/lib/python3.8/dist-packages/gunicorn/arbiter.py", line 242, in handle_chld
    self.reap_workers()
  File "/usr/local/lib/python3.8/dist-packages/gunicorn/arbiter.py", line 525, in reap_workers
    raise HaltServer(reason, self.WORKER_BOOT_ERROR)
gunicorn.errors.HaltServer: <HaltServer 'Worker failed to boot.' 3>
[2020-09-20 14:31:05 +0000] [1] [INFO] Starting gunicorn 20.0.4
[2020-09-20 14:31:05 +0000] [1] [INFO] Listening at: http://0.0.0.0:5000 (1)
[2020-09-20 14:31:05 +0000] [1] [INFO] Using worker: sync
[2020-09-20 14:31:05 +0000] [7] [INFO] Booting worker with pid: 7
[2020-09-20 14:31:05 +0000] [8] [INFO] Booting worker with pid: 8
[2020-09-20 14:31:05 +0000] [9] [INFO] Booting worker with pid: 9
Traceback (most recent call last):
  File "/usr/local/lib/python3.8/dist-packages/gunicorn/arbiter.py", line 209, in run
    self.sleep()
  File "/usr/local/lib/python3.8/dist-packages/gunicorn/arbiter.py", line 357, in sleep
    ready = select.select([self.PIPE[0]], [], [], 1.0)
  File "/usr/local/lib/python3.8/dist-packages/gunicorn/arbiter.py", line 242, in handle_chld
    self.reap_workers()
  File "/usr/local/lib/python3.8/dist-packages/gunicorn/arbiter.py", line 525, in reap_workers
    raise HaltServer(reason, self.WORKER_BOOT_ERROR)
gunicorn.errors.HaltServer: <HaltServer 'Worker failed to boot.' 3>

During handling of the above exception, another exception occurred:

Traceback (most recent call last):
  File "/usr/local/bin/gunicorn", line 8, in <module>
    sys.exit(run())
  File "/usr/local/lib/python3.8/dist-packages/gunicorn/app/wsgiapp.py", line 58, in run
    WSGIApplication("%(prog)s [OPTIONS] [APP_MODULE]").run()
  File "/usr/local/lib/python3.8/dist-packages/gunicorn/app/base.py", line 228, in run
    super().run()
  File "/usr/local/lib/python3.8/dist-packages/gunicorn/app/base.py", line 72, in run
    Arbiter(self).run()
  File "/usr/local/lib/python3.8/dist-packages/gunicorn/arbiter.py", line 229, in run
    self.halt(reason=inst.reason, exit_status=inst.exit_status)
  File "/usr/local/lib/python3.8/dist-packages/gunicorn/arbiter.py", line 342, in halt
    self.stop()
  File "/usr/local/lib/python3.8/dist-packages/gunicorn/arbiter.py", line 393, in stop
    time.sleep(0.1)
  File "/usr/local/lib/python3.8/dist-packages/gunicorn/arbiter.py", line 242, in handle_chld
    self.reap_workers()
  File "/usr/local/lib/python3.8/dist-packages/gunicorn/arbiter.py", line 525, in reap_workers
    raise HaltServer(reason, self.WORKER_BOOT_ERROR)
gunicorn.errors.HaltServer: <HaltServer 'Worker failed to boot.' 3>
[2020-09-20 14:32:13 +0000] [1] [INFO] Starting gunicorn 20.0.4
[2020-09-20 14:32:13 +0000] [1] [INFO] Listening at: http://0.0.0.0:5000 (1)
[2020-09-20 14:32:13 +0000] [1] [INFO] Using worker: sync
[2020-09-20 14:32:13 +0000] [7] [INFO] Booting worker with pid: 7
[2020-09-20 14:32:13 +0000] [8] [INFO] Booting worker with pid: 8
[2020-09-20 14:32:13 +0000] [9] [INFO] Booting worker with pid: 9
Traceback (most recent call last):
  File "/usr/local/lib/python3.8/dist-packages/gunicorn/arbiter.py", line 209, in run
    self.sleep()
  File "/usr/local/lib/python3.8/dist-packages/gunicorn/arbiter.py", line 357, in sleep
    ready = select.select([self.PIPE[0]], [], [], 1.0)
  File "/usr/local/lib/python3.8/dist-packages/gunicorn/arbiter.py", line 242, in handle_chld
    self.reap_workers()
  File "/usr/local/lib/python3.8/dist-packages/gunicorn/arbiter.py", line 525, in reap_workers
    raise HaltServer(reason, self.WORKER_BOOT_ERROR)
gunicorn.errors.HaltServer: <HaltServer 'Worker failed to boot.' 3>

During handling of the above exception, another exception occurred:

Traceback (most recent call last):
  File "/usr/local/bin/gunicorn", line 8, in <module>
    sys.exit(run())
  File "/usr/local/lib/python3.8/dist-packages/gunicorn/app/wsgiapp.py", line 58, in run
    WSGIApplication("%(prog)s [OPTIONS] [APP_MODULE]").run()
  File "/usr/local/lib/python3.8/dist-packages/gunicorn/app/base.py", line 228, in run
    super().run()
  File "/usr/local/lib/python3.8/dist-packages/gunicorn/app/base.py", line 72, in run
    Arbiter(self).run()
  File "/usr/local/lib/python3.8/dist-packages/gunicorn/arbiter.py", line 229, in run
    self.halt(reason=inst.reason, exit_status=inst.exit_status)
  File "/usr/local/lib/python3.8/dist-packages/gunicorn/arbiter.py", line 342, in halt
    self.stop()
  File "/usr/local/lib/python3.8/dist-packages/gunicorn/arbiter.py", line 393, in stop
    time.sleep(0.1)
  File "/usr/local/lib/python3.8/dist-packages/gunicorn/arbiter.py", line 242, in handle_chld
    self.reap_workers()
  File "/usr/local/lib/python3.8/dist-packages/gunicorn/arbiter.py", line 525, in reap_workers
    raise HaltServer(reason, self.WORKER_BOOT_ERROR)
gunicorn.errors.HaltServer: <HaltServer 'Worker failed to boot.' 3>
[2020-09-20 14:33:32 +0000] [1] [INFO] Starting gunicorn 20.0.4
[2020-09-20 14:33:32 +0000] [1] [INFO] Listening at: http://0.0.0.0:5000 (1)
[2020-09-20 14:33:32 +0000] [1] [INFO] Using worker: sync
[2020-09-20 14:33:32 +0000] [7] [INFO] Booting worker with pid: 7
[2020-09-20 14:33:32 +0000] [8] [INFO] Booting worker with pid: 8
[2020-09-20 14:33:32 +0000] [9] [INFO] Booting worker with pid: 9
[2020-09-20 14:37:32 +0000] [1] [INFO] Handling signal: term
[2020-09-20 14:37:32 +0000] [1] [INFO] Shutting down: Master
[2020-09-20 14:37:34 +0000] [1] [INFO] Starting gunicorn 20.0.4
[2020-09-20 14:37:34 +0000] [1] [INFO] Listening at: http://0.0.0.0:5000 (1)
[2020-09-20 14:37:34 +0000] [1] [INFO] Using worker: sync
[2020-09-20 14:37:34 +0000] [7] [INFO] Booting worker with pid: 7
[2020-09-20 14:37:34 +0000] [8] [INFO] Booting worker with pid: 8
[2020-09-20 14:37:34 +0000] [9] [INFO] Booting worker with pid: 9
[2020-09-20 14:38:35 +0000] [1] [INFO] Handling signal: term
[2020-09-20 14:38:36 +0000] [1] [INFO] Shutting down: Master
[2020-09-20 14:38:37 +0000] [1] [INFO] Starting gunicorn 20.0.4
[2020-09-20 14:38:37 +0000] [1] [INFO] Listening at: http://0.0.0.0:5000 (1)
[2020-09-20 14:38:37 +0000] [1] [INFO] Using worker: sync
[2020-09-20 14:38:37 +0000] [7] [INFO] Booting worker with pid: 7
[2020-09-20 14:38:37 +0000] [8] [INFO] Booting worker with pid: 8
[2020-09-20 14:38:37 +0000] [9] [INFO] Booting worker with pid: 9
Traceback (most recent call last):
  File "/usr/local/lib/python3.8/dist-packages/gunicorn/arbiter.py", line 209, in run
    self.sleep()
  File "/usr/local/lib/python3.8/dist-packages/gunicorn/arbiter.py", line 357, in sleep
    ready = select.select([self.PIPE[0]], [], [], 1.0)
  File "/usr/local/lib/python3.8/dist-packages/gunicorn/arbiter.py", line 242, in handle_chld
    self.reap_workers()
  File "/usr/local/lib/python3.8/dist-packages/gunicorn/arbiter.py", line 525, in reap_workers
    raise HaltServer(reason, self.WORKER_BOOT_ERROR)
gunicorn.errors.HaltServer: <HaltServer 'Worker failed to boot.' 3>

During handling of the above exception, another exception occurred:

Traceback (most recent call last):
  File "/usr/local/bin/gunicorn", line 8, in <module>
    sys.exit(run())
  File "/usr/local/lib/python3.8/dist-packages/gunicorn/app/wsgiapp.py", line 58, in run
    WSGIApplication("%(prog)s [OPTIONS] [APP_MODULE]").run()
  File "/usr/local/lib/python3.8/dist-packages/gunicorn/app/base.py", line 228, in run
    super().run()
  File "/usr/local/lib/python3.8/dist-packages/gunicorn/app/base.py", line 72, in run
    Arbiter(self).run()
  File "/usr/local/lib/python3.8/dist-packages/gunicorn/arbiter.py", line 229, in run
    self.halt(reason=inst.reason, exit_status=inst.exit_status)
  File "/usr/local/lib/python3.8/dist-packages/gunicorn/arbiter.py", line 342, in halt
    self.stop()
  File "/usr/local/lib/python3.8/dist-packages/gunicorn/arbiter.py", line 393, in stop
    time.sleep(0.1)
  File "/usr/local/lib/python3.8/dist-packages/gunicorn/arbiter.py", line 242, in handle_chld
    self.reap_workers()
  File "/usr/local/lib/python3.8/dist-packages/gunicorn/arbiter.py", line 525, in reap_workers
    raise HaltServer(reason, self.WORKER_BOOT_ERROR)
gunicorn.errors.HaltServer: <HaltServer 'Worker failed to boot.' 3>
[2020-09-20 14:39:10 +0000] [1] [INFO] Starting gunicorn 20.0.4
[2020-09-20 14:39:10 +0000] [1] [INFO] Listening at: http://0.0.0.0:5000 (1)
[2020-09-20 14:39:10 +0000] [1] [INFO] Using worker: sync
[2020-09-20 14:39:10 +0000] [8] [INFO] Booting worker with pid: 8
[2020-09-20 14:39:10 +0000] [9] [INFO] Booting worker with pid: 9
[2020-09-20 14:39:10 +0000] [10] [INFO] Booting worker with pid: 10
[2020-09-20 15:17:18 +0000] [1] [INFO] Handling signal: term
[2020-09-20 15:17:18 +0000] [1] [INFO] Shutting down: Master
[2020-09-20 15:17:20 +0000] [1] [INFO] Starting gunicorn 20.0.4
[2020-09-20 15:17:20 +0000] [1] [INFO] Listening at: http://0.0.0.0:5000 (1)
[2020-09-20 15:17:20 +0000] [1] [INFO] Using worker: sync
[2020-09-20 15:17:20 +0000] [7] [INFO] Booting worker with pid: 7
[2020-09-20 15:17:20 +0000] [8] [INFO] Booting worker with pid: 8
[2020-09-20 15:17:20 +0000] [9] [INFO] Booting worker with pid: 9
[2020-09-20 15:21:13 +0000] [1] [INFO] Handling signal: term
[2020-09-20 15:21:13 +0000] [1] [INFO] Shutting down: Master
[2020-09-20 15:21:15 +0000] [1] [INFO] Starting gunicorn 20.0.4
[2020-09-20 15:21:15 +0000] [1] [INFO] Listening at: http://0.0.0.0:5000 (1)
[2020-09-20 15:21:15 +0000] [1] [INFO] Using worker: sync
[2020-09-20 15:21:15 +0000] [7] [INFO] Booting worker with pid: 7
[2020-09-20 15:21:15 +0000] [8] [INFO] Booting worker with pid: 8
[2020-09-20 15:21:15 +0000] [9] [INFO] Booting worker with pid: 9
[2020-09-20 15:33:54 +0000] [1] [INFO] Handling signal: term
[2020-09-20 15:33:54 +0000] [1] [INFO] Shutting down: Master
[2020-09-20 15:33:56 +0000] [1] [INFO] Starting gunicorn 20.0.4
[2020-09-20 15:33:56 +0000] [1] [INFO] Listening at: http://0.0.0.0:5000 (1)
[2020-09-20 15:33:56 +0000] [1] [INFO] Using worker: sync
[2020-09-20 15:33:56 +0000] [7] [INFO] Booting worker with pid: 7
[2020-09-20 15:33:56 +0000] [8] [INFO] Booting worker with pid: 8
[2020-09-20 15:33:56 +0000] [9] [INFO] Booting worker with pid: 9
Traceback (most recent call last):
  File "/usr/local/lib/python3.8/dist-packages/gunicorn/arbiter.py", line 209, in run
    self.sleep()
  File "/usr/local/lib/python3.8/dist-packages/gunicorn/arbiter.py", line 357, in sleep
    ready = select.select([self.PIPE[0]], [], [], 1.0)
  File "/usr/local/lib/python3.8/dist-packages/gunicorn/arbiter.py", line 242, in handle_chld
    self.reap_workers()
  File "/usr/local/lib/python3.8/dist-packages/gunicorn/arbiter.py", line 525, in reap_workers
    raise HaltServer(reason, self.WORKER_BOOT_ERROR)
gunicorn.errors.HaltServer: <HaltServer 'Worker failed to boot.' 3>

During handling of the above exception, another exception occurred:

Traceback (most recent call last):
  File "/usr/local/bin/gunicorn", line 8, in <module>
    sys.exit(run())
  File "/usr/local/lib/python3.8/dist-packages/gunicorn/app/wsgiapp.py", line 58, in run
    WSGIApplication("%(prog)s [OPTIONS] [APP_MODULE]").run()
  File "/usr/local/lib/python3.8/dist-packages/gunicorn/app/base.py", line 228, in run
    super().run()
  File "/usr/local/lib/python3.8/dist-packages/gunicorn/app/base.py", line 72, in run
    Arbiter(self).run()
  File "/usr/local/lib/python3.8/dist-packages/gunicorn/arbiter.py", line 229, in run
    self.halt(reason=inst.reason, exit_status=inst.exit_status)
  File "/usr/local/lib/python3.8/dist-packages/gunicorn/arbiter.py", line 342, in halt
    self.stop()
  File "/usr/local/lib/python3.8/dist-packages/gunicorn/arbiter.py", line 393, in stop
    time.sleep(0.1)
  File "/usr/local/lib/python3.8/dist-packages/gunicorn/arbiter.py", line 242, in handle_chld
    self.reap_workers()
  File "/usr/local/lib/python3.8/dist-packages/gunicorn/arbiter.py", line 525, in reap_workers
    raise HaltServer(reason, self.WORKER_BOOT_ERROR)
gunicorn.errors.HaltServer: <HaltServer 'Worker failed to boot.' 3>
[2020-09-20 15:35:06 +0000] [1] [INFO] Starting gunicorn 20.0.4
[2020-09-20 15:35:06 +0000] [1] [INFO] Listening at: http://0.0.0.0:5000 (1)
[2020-09-20 15:35:06 +0000] [1] [INFO] Using worker: sync
[2020-09-20 15:35:06 +0000] [7] [INFO] Booting worker with pid: 7
[2020-09-20 15:35:07 +0000] [8] [INFO] Booting worker with pid: 8
[2020-09-20 15:35:07 +0000] [9] [INFO] Booting worker with pid: 9
[2020-09-20 15:35:07 +0000] [1] [INFO] Shutting down: Master
[2020-09-20 15:35:07 +0000] [1] [INFO] Reason: Worker failed to boot.
[2020-09-20 15:36:59 +0000] [1] [INFO] Starting gunicorn 20.0.4
[2020-09-20 15:36:59 +0000] [1] [INFO] Listening at: http://0.0.0.0:5000 (1)
[2020-09-20 15:36:59 +0000] [1] [INFO] Using worker: sync
[2020-09-20 15:36:59 +0000] [7] [INFO] Booting worker with pid: 7
[2020-09-20 15:37:00 +0000] [8] [INFO] Booting worker with pid: 8
[2020-09-20 15:37:00 +0000] [9] [INFO] Booting worker with pid: 9
Traceback (most recent call last):
  File "/usr/local/lib/python3.8/dist-packages/gunicorn/arbiter.py", line 209, in run
    self.sleep()
  File "/usr/local/lib/python3.8/dist-packages/gunicorn/arbiter.py", line 357, in sleep
    ready = select.select([self.PIPE[0]], [], [], 1.0)
  File "/usr/local/lib/python3.8/dist-packages/gunicorn/arbiter.py", line 242, in handle_chld
    self.reap_workers()
  File "/usr/local/lib/python3.8/dist-packages/gunicorn/arbiter.py", line 525, in reap_workers
    raise HaltServer(reason, self.WORKER_BOOT_ERROR)
gunicorn.errors.HaltServer: <HaltServer 'Worker failed to boot.' 3>

During handling of the above exception, another exception occurred:

Traceback (most recent call last):
  File "/usr/local/bin/gunicorn", line 8, in <module>
    sys.exit(run())
  File "/usr/local/lib/python3.8/dist-packages/gunicorn/app/wsgiapp.py", line 58, in run
    WSGIApplication("%(prog)s [OPTIONS] [APP_MODULE]").run()
  File "/usr/local/lib/python3.8/dist-packages/gunicorn/app/base.py", line 228, in run
    super().run()
  File "/usr/local/lib/python3.8/dist-packages/gunicorn/app/base.py", line 72, in run
    Arbiter(self).run()
  File "/usr/local/lib/python3.8/dist-packages/gunicorn/arbiter.py", line 229, in run
    self.halt(reason=inst.reason, exit_status=inst.exit_status)
  File "/usr/local/lib/python3.8/dist-packages/gunicorn/arbiter.py", line 342, in halt
    self.stop()
  File "/usr/local/lib/python3.8/dist-packages/gunicorn/arbiter.py", line 393, in stop
    time.sleep(0.1)
  File "/usr/local/lib/python3.8/dist-packages/gunicorn/arbiter.py", line 242, in handle_chld
    self.reap_workers()
  File "/usr/local/lib/python3.8/dist-packages/gunicorn/arbiter.py", line 525, in reap_workers
    raise HaltServer(reason, self.WORKER_BOOT_ERROR)
gunicorn.errors.HaltServer: <HaltServer 'Worker failed to boot.' 3>
[2020-09-20 15:38:25 +0000] [1] [INFO] Starting gunicorn 20.0.4
[2020-09-20 15:38:25 +0000] [1] [INFO] Listening at: http://0.0.0.0:5000 (1)
[2020-09-20 15:38:25 +0000] [1] [INFO] Using worker: sync
[2020-09-20 15:38:25 +0000] [7] [INFO] Booting worker with pid: 7
[2020-09-20 15:38:25 +0000] [8] [INFO] Booting worker with pid: 8
[2020-09-20 15:38:25 +0000] [9] [INFO] Booting worker with pid: 9
Traceback (most recent call last):
  File "/usr/local/lib/python3.8/dist-packages/gunicorn/arbiter.py", line 209, in run
    self.sleep()
  File "/usr/local/lib/python3.8/dist-packages/gunicorn/arbiter.py", line 357, in sleep
    ready = select.select([self.PIPE[0]], [], [], 1.0)
  File "/usr/local/lib/python3.8/dist-packages/gunicorn/arbiter.py", line 242, in handle_chld
    self.reap_workers()
  File "/usr/local/lib/python3.8/dist-packages/gunicorn/arbiter.py", line 525, in reap_workers
    raise HaltServer(reason, self.WORKER_BOOT_ERROR)
gunicorn.errors.HaltServer: <HaltServer 'Worker failed to boot.' 3>

During handling of the above exception, another exception occurred:

Traceback (most recent call last):
  File "/usr/local/bin/gunicorn", line 8, in <module>
    sys.exit(run())
  File "/usr/local/lib/python3.8/dist-packages/gunicorn/app/wsgiapp.py", line 58, in run
    WSGIApplication("%(prog)s [OPTIONS] [APP_MODULE]").run()
  File "/usr/local/lib/python3.8/dist-packages/gunicorn/app/base.py", line 228, in run
    super().run()
  File "/usr/local/lib/python3.8/dist-packages/gunicorn/app/base.py", line 72, in run
    Arbiter(self).run()
  File "/usr/local/lib/python3.8/dist-packages/gunicorn/arbiter.py", line 229, in run
    self.halt(reason=inst.reason, exit_status=inst.exit_status)
  File "/usr/local/lib/python3.8/dist-packages/gunicorn/arbiter.py", line 342, in halt
    self.stop()
  File "/usr/local/lib/python3.8/dist-packages/gunicorn/arbiter.py", line 393, in stop
    time.sleep(0.1)
  File "/usr/local/lib/python3.8/dist-packages/gunicorn/arbiter.py", line 242, in handle_chld
    self.reap_workers()
  File "/usr/local/lib/python3.8/dist-packages/gunicorn/arbiter.py", line 525, in reap_workers
    raise HaltServer(reason, self.WORKER_BOOT_ERROR)
gunicorn.errors.HaltServer: <HaltServer 'Worker failed to boot.' 3>
[2020-09-20 15:42:54 +0000] [1] [INFO] Starting gunicorn 20.0.4
[2020-09-20 15:42:54 +0000] [1] [INFO] Listening at: http://0.0.0.0:5000 (1)
[2020-09-20 15:42:54 +0000] [1] [INFO] Using worker: sync
[2020-09-20 15:42:54 +0000] [7] [INFO] Booting worker with pid: 7
[2020-09-20 15:42:54 +0000] [8] [INFO] Booting worker with pid: 8
[2020-09-20 15:42:54 +0000] [9] [INFO] Booting worker with pid: 9
Traceback (most recent call last):
  File "/usr/local/lib/python3.8/dist-packages/gunicorn/arbiter.py", line 209, in run
    self.sleep()
  File "/usr/local/lib/python3.8/dist-packages/gunicorn/arbiter.py", line 357, in sleep
    ready = select.select([self.PIPE[0]], [], [], 1.0)
  File "/usr/local/lib/python3.8/dist-packages/gunicorn/arbiter.py", line 242, in handle_chld
    self.reap_workers()
  File "/usr/local/lib/python3.8/dist-packages/gunicorn/arbiter.py", line 525, in reap_workers
    raise HaltServer(reason, self.WORKER_BOOT_ERROR)
gunicorn.errors.HaltServer: <HaltServer 'Worker failed to boot.' 3>

During handling of the above exception, another exception occurred:

Traceback (most recent call last):
  File "/usr/local/bin/gunicorn", line 8, in <module>
    sys.exit(run())
  File "/usr/local/lib/python3.8/dist-packages/gunicorn/app/wsgiapp.py", line 58, in run
    WSGIApplication("%(prog)s [OPTIONS] [APP_MODULE]").run()
  File "/usr/local/lib/python3.8/dist-packages/gunicorn/app/base.py", line 228, in run
    super().run()
  File "/usr/local/lib/python3.8/dist-packages/gunicorn/app/base.py", line 72, in run
    Arbiter(self).run()
  File "/usr/local/lib/python3.8/dist-packages/gunicorn/arbiter.py", line 229, in run
    self.halt(reason=inst.reason, exit_status=inst.exit_status)
  File "/usr/local/lib/python3.8/dist-packages/gunicorn/arbiter.py", line 342, in halt
    self.stop()
  File "/usr/local/lib/python3.8/dist-packages/gunicorn/arbiter.py", line 393, in stop
    time.sleep(0.1)
  File "/usr/local/lib/python3.8/dist-packages/gunicorn/arbiter.py", line 242, in handle_chld
    self.reap_workers()
  File "/usr/local/lib/python3.8/dist-packages/gunicorn/arbiter.py", line 525, in reap_workers
    raise HaltServer(reason, self.WORKER_BOOT_ERROR)
gunicorn.errors.HaltServer: <HaltServer 'Worker failed to boot.' 3>
[2020-09-20 15:43:03 +0000] [1] [INFO] Starting gunicorn 20.0.4
[2020-09-20 15:43:03 +0000] [1] [INFO] Listening at: http://0.0.0.0:5000 (1)
[2020-09-20 15:43:03 +0000] [1] [INFO] Using worker: sync
[2020-09-20 15:43:03 +0000] [8] [INFO] Booting worker with pid: 8
[2020-09-20 15:43:03 +0000] [9] [INFO] Booting worker with pid: 9
[2020-09-20 15:43:03 +0000] [10] [INFO] Booting worker with pid: 10
Traceback (most recent call last):
  File "/usr/local/lib/python3.8/dist-packages/gunicorn/arbiter.py", line 209, in run
    self.sleep()
  File "/usr/local/lib/python3.8/dist-packages/gunicorn/arbiter.py", line 357, in sleep
    ready = select.select([self.PIPE[0]], [], [], 1.0)
  File "/usr/local/lib/python3.8/dist-packages/gunicorn/arbiter.py", line 242, in handle_chld
    self.reap_workers()
  File "/usr/local/lib/python3.8/dist-packages/gunicorn/arbiter.py", line 525, in reap_workers
    raise HaltServer(reason, self.WORKER_BOOT_ERROR)
gunicorn.errors.HaltServer: <HaltServer 'Worker failed to boot.' 3>

During handling of the above exception, another exception occurred:

Traceback (most recent call last):
  File "/usr/local/bin/gunicorn", line 8, in <module>
    sys.exit(run())
  File "/usr/local/lib/python3.8/dist-packages/gunicorn/app/wsgiapp.py", line 58, in run
    WSGIApplication("%(prog)s [OPTIONS] [APP_MODULE]").run()
  File "/usr/local/lib/python3.8/dist-packages/gunicorn/app/base.py", line 228, in run
    super().run()
  File "/usr/local/lib/python3.8/dist-packages/gunicorn/app/base.py", line 72, in run
    Arbiter(self).run()
  File "/usr/local/lib/python3.8/dist-packages/gunicorn/arbiter.py", line 229, in run
    self.halt(reason=inst.reason, exit_status=inst.exit_status)
  File "/usr/local/lib/python3.8/dist-packages/gunicorn/arbiter.py", line 342, in halt
    self.stop()
  File "/usr/local/lib/python3.8/dist-packages/gunicorn/arbiter.py", line 393, in stop
    time.sleep(0.1)
  File "/usr/local/lib/python3.8/dist-packages/gunicorn/arbiter.py", line 242, in handle_chld
    self.reap_workers()
  File "/usr/local/lib/python3.8/dist-packages/gunicorn/arbiter.py", line 525, in reap_workers
    raise HaltServer(reason, self.WORKER_BOOT_ERROR)
gunicorn.errors.HaltServer: <HaltServer 'Worker failed to boot.' 3>
[2020-09-20 15:43:29 +0000] [1] [INFO] Starting gunicorn 20.0.4
[2020-09-20 15:43:29 +0000] [1] [INFO] Listening at: http://0.0.0.0:5000 (1)
[2020-09-20 15:43:29 +0000] [1] [INFO] Using worker: sync
[2020-09-20 15:43:29 +0000] [7] [INFO] Booting worker with pid: 7
[2020-09-20 15:43:29 +0000] [8] [INFO] Booting worker with pid: 8
[2020-09-20 15:43:29 +0000] [9] [INFO] Booting worker with pid: 9
